Workbook

Sheet DSLP RAW MATERIALS WK 2
C1: RAW MATERIAL BALANCE FOR WEEK WEEK 2 (4TH-10TH JAN, 2026). | F1: =G1-1 -> 46043.748 | G1: =NOW() -> 46044.748 | I1: ="Week"&" "&WEEKNUM(F1) -> Week 4
B2: SN | C2: RAW MATERIALS | D2: Requirements in Kg / Unit | E2: Monthly RQMT by Budget | F2: Stock At Hand | G2: Stock In Transit | H2: Total Stock | I2: Stock Holding / Month | J2: Remark / Planned Request | K2: Status
B3: A | C3: ACTIVE PHARMACEUTICAL INGREDIENT
A4: SN | B4: 1 | C4: Amprolium | D4: 2123 | E4: =D4/9 -> 235.88889 | F4: =(7*25)+17.2 -> 192.2 | H4: =F4+G4 -> 192.2 | I4: =H4/E4 -> 0.81479039 | J4: REQUEST PLACED
A5: 1 | B5: =B4+1 -> 2 | C5: Diaveridin | D5: 352 | E5: =D5/9 -> 39.111111 | F5: =180.4 -> 180.4 | H5: =F5+G5 -> 180.4 | I5: =H5/E5 -> 4.6125 | J5: OK
A6: =A5+1 -> 2 | B6: =B5+1 -> 3 | C6: Sulphaquinoxaline | D6: 1854 | E6: =D6/9 -> 206 | F6: =(3*9*25)+13.75 -> 688.75 | H6: =F6+G6 -> 688.75 | I6: =H6/E6 -> 3.3434466 | J6: OK
A7: =A6+1 -> 3 | B7: =B6+1 -> 4 | C7: Sulphamethoxazole | D7: 320 | E7: =D7/9 -> 35.555556 | F7: =21.25 -> 21.25 | H7: =F7+G7 -> 21.25 | I7: =H7/E7 -> 0.59765625
A8: =A7+1 -> 4 | B8: =B7+1 -> 5 | C8: Trimethoprim | D8: 154 | E8: =D8/9 -> 17.111111 | F8: =8.7 -> 8.7 | H8: =F8+G8 -> 8.7 | I8: =H8/E8 -> 0.50844156 | J8: REQUEST PLACED | K8: PROCUREMENT VIEW
A9: =A8+1 -> 5 | B9: =B8+1 -> 6 | C9: Pefloxacin | D9: 983.3664 | E9: =D9/9 -> 109.26293 | F9: 4.6 | H9: =F9+G9 -> 4.6 | I9: =H9/E9 -> 0.042100279 | K9: PROCUREMENT VIEW
A10: =A9+1 -> 6 | B10: =B9+1 -> 7 | C10: Gentamycin | D10: 1841 | E10: =D10/9 -> 204.55556 | F10: =(7*16.18)+12.55 -> 125.81 | H10: =F10+G10 -> 125.81 | I10: =H10/E10 -> 0.61504074 | J10: REQUEST PLACED
A11: =A10+1 -> 7 | B11: =B10+1 -> 8 | C11: Doxycycline | D11: 1225 | E11: =D11/9 -> 136.11111 | F11: =(5*25)+4.95 -> 129.95 | H11: =F11+G11 -> 129.95 | I11: =H11/E11 -> 0.95473469 | J11: OK
A12: =A11+1 -> 8 | B12: =B11+1 -> 9 | C12: Neomycin | D12: 1555 | E12: =D12/9 -> 172.77778 | F12: =(11*25)+6 -> 281 | H12: =F12+G12 -> 281 | I12: =H12/E12 -> 1.6263666 | J12: OK
B13: =B12+1 -> 10 | C13: Tylosine | D13: 3673 | E13: =D13/9 -> 408.11111 | F13: =(15*12)+1.7 -> 181.7 | H13: =F13+G13 -> 181.7 | I13: =H13/E13 -> 0.44522189 | J13: REQUEST PLACED
A14: =A12+1 -> 9 | B14: =B13+1 -> 11 | C14: Levamisole | D14: 669.3768 | E14: =D14/9 -> 74.3752 | F14: =19.75 -> 19.75 | H14: =F14+G14 -> 19.75 | I14: =H14/E14 -> 0.2655455 | J14: REQUEST PLACED | K14: PROCUREMENT VIEW
A15: =A14+1 -> 10 | B15: =B14+1 -> 12 | C15: Ciprofoxacine | D15: 3518 | E15: =D15/9 -> 390.88889 | F15: =735.65 -> 735.65 | H15: =F15+G15 -> 735.65 | I15: =H15/E15 -> 1.8819926 | J15: REQUEST PLACED
A16: =A15+1 -> 11 | B16: =B15+1 -> 13 | C16: Enrofloxacine | D16: 3245 | E16: =D16/9 -> 360.55556 | F16: 10.1 | H16: =F16+G16 -> 10.1 | I16: =H16/E16 -> 0.028012327 | J16: REQUEST PLACED | K16: PROCUREMENT VIEW
A17: =A16+1 -> 12 | B17: =B16+1 -> 14 | C17: Ivermectin | D17: 76.628832 | E17: =D17/9 -> 8.5143147 | F17: =17.5 -> 17.5 | H17: =F17+G17 -> 17.5 | I17: =H17/E17 -> 2.0553621
A18: =A17+1 -> 13 | B18: =B17+1 -> 15 | C18: Povidone | D18: 2622.24 | E18: =D18/9 -> 291.36 | F18: =3.3-2.4 -> 0.9 | H18: =F18+G18 -> 0.9 | I18: =H18/E18 -> 0.0030889621 | J18: REQUEST PLACED | K18: PROCUREMENT VIEW
A19: =A18+1 -> 14 | B19: =B18+1 -> 16 | C19: Divertamin B Plus | D19: 114 | E19: =D19/9 -> 12.666667 | F19: 0 | H19: =F19+G19 -> 0 | I19: =H19/E19 -> 0
A20: =A19+1 -> 15 | B20: =B19+1 -> 17 | C20: Vitamin A ACETATE | E20: =D20/9 -> 0 | F20: =150.8+36.9 -> 187.7 | H20: =F20+G20 -> 187.7 | I20: =H20/E20 -> #DIV/0! | J20: TO BE SOLD OFF
A21: =A20+1 -> 16 | B21: =B20+1 -> 18 | C21: Vitamin A Palmitate | E21: =D21/9 -> 0 | F21: =37.85 -> 37.85 | H21: =F21+G21 -> 37.85 | I21: =H21/E21 -> #DIV/0!
A22: =A21+1 -> 17 | B22: =B21+1 -> 19 | C22: VITAMIN B12(CYANOCOLOBALAMIN) | E22: =D22/9 -> 0 | F22: 0.09 | H22: =F22+G22 -> 0.09 | I22: =H22/E22 -> #DIV/0!
A23: =A22+1 -> 18 | B23: =B22+1 -> 20 | C23: RIBOFLAVIN 98% (VIT B 2) | E23: =D23/9 -> 0 | F23: =37.6 -> 37.6 | H23: =F23+G23 -> 37.6 | I23: =H23/E23 -> #DIV/0!
A24: =A23+1 -> 19 | B24: =B23+1 -> 21 | C24: Vitamin C Coated | E24: =D24/9 -> 0 | F24: =2.5 -> 2.5 | H24: =F24+G24 -> 2.5 | I24: =H24/E24 -> #DIV/0!
A25: =A24+1 -> 20 | B25: =B24+1 -> 22 | C25: Vitamin D3 | E25: =D25/9 -> 0 | F25: =22 -> 22 | H25: =F25+G25 -> 22 | I25: =H25/E25 -> #DIV/0!
A26: =A25+1 -> 21 | B26: =B25+1 -> 23 | C26: Vitamin E liquid | E26: =D26/9 -> 0 | F26: =84.6+40 -> 124.6 | H26: =F26+G26 -> 124.6 | I26: =H26/E26 -> #DIV/0!
B27: =B26+1 -> 24 | C27: vitamin E powder | E27: =D27/9 -> 0 | F27: =21.6 -> 21.6 | H27: =F27+G27 -> 21.6 | I27: =H27/E27 -> #DIV/0!
A28: =A26+1 -> 22 | B28: =B27+1 -> 25 | C28: Vitamin K3 | E28: =D28/9 -> 0 | F28: =11.95 -> 11.95 | H28: =F28+G28 -> 11.95 | I28: =H28/E28 -> #DIV/0!
A29: =A28+1 -> 23 | B29: =B28+1 -> 26 | C29: Abendazol | E29: =D29/9 -> 0 | F29: =24.45+100 -> 124.45 | H29: =F29+G29 -> 124.45 | I29: =H29/E29 -> #DIV/0!
A30: =A29+1 -> 24 | B30: =B29+1 -> 27 | C30: Ammonium citrate | E30: =D30/9 -> 0 | F30: =400+132.05 -> 532.05 | H30: =F30+G30 -> 532.05 | I30: =H30/E30 -> #DIV/0! | J30: EXCESS STOCK PART TO BE SOLD OFF
A31: =A30+1 -> 25 | B31: =B30+1 -> 28 | C31: Ascorbic Acid | E31: =D31/9 -> 0 | F31: =121.1 -> 121.1 | H31: =F31+G31 -> 121.1 | I31: =H31/E31 -> #DIV/0! | J31: EXCESS STOCK PART TO BE SOLD OFF
B32: =B31+1 -> 29 | C32: biotin | E32: =D32/9 -> 0 | F32: 0.65 | H32: =F32+G32 -> 0.65 | I32: =H32/E32 -> #DIV/0!
B33: =B32+1 -> 30 | C33: calcium gluconate | E33: =D33/9 -> 0 | F33: =19.05 -> 19.05 | H33: =F33+G33 -> 19.05 | I33: =H33/E33 -> #DIV/0! | K33: PROCUREMENT VIEW
B34: =B33+1 -> 31 | C34: choline chloride | E34: =D34/9 -> 0 | H34: =F34+G34 -> 0 | I34: =H34/E34 -> #DIV/0! | K34: PROCUREMENT VIEW
B35: =B34+1 -> 32 | C35: diclazuril | E35: =D35/9 -> 0 | F35: =5+25 -> 30 | H35: =F35+G35 -> 30 | I35: =H35/E35 -> #DIV/0!
B36: =B35+1 -> 33 | C36: d-calcium | E36: =D36/9 -> 0 | F36: 0 | H36: =F36+G36 -> 0 | I36: =H36/E36 -> #DIV/0!
B37: =B36+1 -> 34 | C37: folic acid | E37: =D37/9 -> 0 | F37: =23.35 -> 23.35 | H37: =F37+G37 -> 23.35 | I37: =H37/E37 -> #DIV/0!
B38: =B37+1 -> 35 | C38: inositol | E38: =D38/9 -> 0 | F38: 25 | H38: =F38+G38 -> 25 | I38: =H38/E38 -> #DIV/0! | J38: EXCESS STOCK PART TO BE SOLD OFF
B39: =B38+1 -> 36 | C39: l-lysin | E39: =D39/9 -> 0 | F39: =24.4 -> 24.4 | H39: =F39+G39 -> 24.4 | I39: =H39/E39 -> #DIV/0!
B40: =B39+1 -> 37 | C40: nicotinamade | E40: =D40/9 -> 0 | F40: 10.1 | H40: =F40+G40 -> 10.1 | I40: =H40/E40 -> #DIV/0! | K40: PROCUREMENT VIEW
...

Sheet DSLP FG WK 2
B1: DSLP INVENTORY REPORT FOR WEEK 2 (4TH-10TH JAN, 2026).
C2: =D2-1 -> 46043.748 | D2: =NOW() -> 46044.748 | G2: ="Week"&" "&WEEKNUM(C2) -> Week 4
B3: SN | C3: FINISHED PRODUCTS | D3: CONDITIONING | E3: REWORK | F3: LAGOS | G3: OWERRI | H3: ABJ | I3: AWE | J3: JOS | K3: KADUNA | L3: TOTAL | M3: IN CARTON | N3: PRODUCT STATUS | P3: FAST MOVING | Q3: SLOW MOVING
A4: SN | B4: 1 | C4: AMPROLIUM 30 - 100GRM | D4: 96 | F4: 2358 | G4: =192 -> 192 | I4: =391 -> 391 | J4: =425-10+480 -> 895 | L4: =K4+J4+I4+H4+G4+F4 -> 3836 | M4: =L4/D4 -> 39.958333 | N4: FAST MOVING | O4: NOV, 2027
A5: 1 | B5: =B4+1 -> 2 | C5: COXSTOP 100GRM | D5: 96 | E5: 1296 | F5: 2256 | I5: =48 -> 48 | J5: =576 -> 576 | L5: =K5+J5+I5+H5+G5+F5 -> 2880 | M5: =L5/D5 -> 30 | N5: FAST MOVING | O5: MAR, 2027
A6: =A5+1 -> 2 | B6: =B5+1 -> 3 | C6: COXSTOP 30GRM | D6: 216 | I6: 0 | J6: 0 | L6: =K6+J6+I6+H6+G6+F6 -> 0 | M6: =L6/D6 -> 0 | N6: SLOW MOVING
A7: =A6+1 -> 3 | B7: =B6+1 -> 4 | C7: DISULTRIM 100GRM | D7: 96 | E7: =751 -> 751 | F7: 5 | I7: =47 -> 47 | J7: =75 -> 75 | L7: =K7+J7+I7+H7+G7+F7 -> 127 | M7: =L7/D7 -> 1.3229167 | N7: SLOW MOVING | O7: OCT, 2027
A8: =A7+1 -> 4 | B8: =B7+1 -> 5 | C8: DISULTRIM 50GRM | D8: 192 | H8: 0 | L8: =K8+J8+I8+H8+G8+F8 -> 0 | M8: =L8/D8 -> 0 | N8: SLOW MOVING
A9: =A8+1 -> 5 | B9: =B8+1 -> 6 | C9: DIVERCAL-D | D9: 12 | F9: 9 | G9: =26 -> 26 | H9: 0 | I9: =3 -> 3 | J9: =89 -> 89 | L9: =K9+J9+I9+H9+G9+F9 -> 127 | M9: =L9/D9 -> 10.583333 | N9: FAST MOVING | O9: AUG, 2027
A10: =A9+1 -> 6 | B10: =B9+1 -> 7 | C10: DIVERCIPRO 1 LTR | D10: 12 | E10: =65 -> 65 | F10: =1031 -> 1031 | H10: 0 | I10: =200 -> 200 | J10: =30+120 -> 150 | L10: =K10+J10+I10+H10+G10+F10 -> 1381 | M10: =L10/D10 -> 115.08333 | N10: FAST MOVING | O10: OCT /NOV, 2027
A11: =A10+1 -> 7 | B11: =B10+1 -> 8 | C11: DIVERCOOL C 1 Ltr | D11: 12 | L11: =K11+J11+I11+H11+G11+F11 -> 0 | M11: =L11/D11 -> 0 | N11: SLOW MOVING
A12: =A11+1 -> 8 | B12: =B11+1 -> 9 | C12: DIVERCOOL C 25Litres | D12: 1 | F12: 15 | I12: =10 -> 10 | J12: =2 -> 2 | L12: =K12+J12+I12+H12+G12+F12 -> 27 | M12: =L12/D12 -> 27 | N12: NEW PRODUCT ON OBSERVATION | O12: JAN ,2027
B13: =B12+1 -> 10 | C13: DIVERCOX 1 LITRE | D13: 12 | L13: =K13+J13+I13+H13+G13+F13 -> 0 | M13: =L13/D13 -> 0 | N13: SLOW MOVING
A14: =A12+1 -> 9 | B14: =B13+1 -> 11 | C14: DIVERDAZOLE 1 LTR | D14: 12 | F14: =12*12+3 -> 147 | I14: 12 | J14: =60+60 -> 120 | L14: =K14+J14+I14+H14+G14+F14 -> 279 | M14: =L14/D14 -> 23.25 | N14: SLOW MOVING | O14: JUNE, 2027
A15: =A14+1 -> 10 | B15: =B14+1 -> 12 | C15: DIVERFLOX 100GRM | D15: 96 | E15: 2 | I15: =28 -> 28 | J15: =736 -> 736 | L15: =K15+J15+I15+H15+G15+F15 -> 764 | M15: =L15/D15 -> 7.9583333 | N15: SLOW MOVING | O15: NOV, 2027
A16: =A15+1 -> 11 | B16: =B15+1 -> 13 | C16: DIVERFUME 1KG | D16: 12 | J16: 0 | L16: =K16+J16+I16+H16+G16+F16 -> 0 | M16: =L16/D16 -> 0 | N16: SLOW MOVING
A17: =A16+1 -> 12 | B17: =B16+1 -> 14 | C17: DIVERGEN D 100GRM | D17: 96 | F17: 1720 | I17: =288 -> 288 | J17: =62 -> 62 | L17: =K17+J17+I17+H17+G17+F17 -> 2070 | M17: =L17/D17 -> 21.5625 | N17: FAST MOVING | O17: DEC, 2027
A18: =A17+1 -> 13 | B18: =B17+1 -> 15 | C18: DIVERTAMIN | D18: 96 | E18: 2 | F18: 357 | G18: 192 | I18: =158 -> 158 | J18: =770+288 -> 1058 | L18: =K18+J18+I18+H18+G18+F18 -> 1765 | M18: =L18/D18 -> 18.385417 | N18: FAST MOVING | O18: SEP, 2027
A19: =A18+1 -> 14 | B19: =B18+1 -> 16 | C19: DIVERVITE 1 LTRE | D19: 12 | E19: 2 | F19: 70 | G19: =6 -> 6 | J19: =46 -> 46 | L19: =K19+J19+I19+H19+G19+F19 -> 122 | M19: =L19/D19 -> 10.166667 | N19: FAST MOVING | O19: SEP, 2027
A20: =A19+1 -> 15 | B20: =B19+1 -> 17 | C20: DOXINEO 100GRM | D20: 96 | E20: 4 | L20: =K20+J20+I20+H20+G20+F20 -> 0 | M20: =L20/D20 -> 0 | N20: FAST MOVING
A21: =A20+1 -> 16 | B21: =B20+1 -> 18 | C21: DOXINEO 50GRM | D21: 192 | F21: 678 | I21: =216 -> 216 | J21: =585+576 -> 1161 | L21: =K21+J21+I21+H21+G21+F21 -> 2055 | M21: =L21/D21 -> 10.703125 | N21: SLOW MOVING | O21: AUG, 2027
A22: =A21+1 -> 17 | B22: =B21+1 -> 19 | C22: ENRO 1 LTR | D22: 12 | F22: 1 | G22: 19 | I22: =22 -> 22 | J22: =0 -> 0 | L22: =K22+J22+I22+H22+G22+F22 -> 42 | M22: =L22/D22 -> 3.5 | N22: FAST MOVING | O22: MAY, 2027
A23: =A22+1 -> 18 | B23: =B22+1 -> 20 | C23: GENTYLO - 100 GRM | D23: 96 | F23: 199 | G23: =40 -> 40 | I23: =236 -> 236 | J23: =871-192 -> 679 | L23: =K23+J23+I23+H23+G23+F23 -> 1154 | M23: =L23/D23 -> 12.020833 | N23: FAST MOVING | O23: SEP, 2027
A24: =A23+1 -> 19 | B24: =B23+1 -> 21 | C24: IVERTMECTIN 1 LTR | D24: 12 | F24: =248+492+498 -> 1238 | G24: =6+12-12 -> 6 | I24: =80 -> 80 | J24: =59 -> 59 | L24: =K24+J24+I24+H24+G24+F24 -> 1383 | M24: =L24/D24 -> 115.25 | N24: FAST MOVING | O24: MAY/JUNE 2027
A25: =A24+1 -> 20 | B25: =B24+1 -> 22 | C25: DIVERSEL E 1 LITRE | D25: 12 | F25: =(6*5+4)*12+3 -> 411 | G25: 20 | I25: =240 -> 240 | J25: 0 | L25: =K25+J25+I25+H25+G25+F25 -> 671 | M25: =L25/D25 -> 55.916667 | N25: NEW PRODUCT ON OBSERVATION | O25: AUG, 2027
A26: =A25+1 -> 21 | B26: =B25+1 -> 23 | C26: DIVERSEL E 25 LITRES | D26: 1 | M26: =L26/D26 -> 0 | N26: NEW PRODUCT ON OBSERVATION
B27: =B26+1 -> 24 | C27: LEVASTAR 10OGRM | D27: 96 | E27: 11 | F27: =3372 -> 3372 | I27: =224 -> 224 | J27: =961 -> 961 | L27: =K27+J27+I27+H27+G27+F27 -> 4557 | M27: =L27/D27 -> 47.46875 | N27: SLOW MOVING | O27: OCT, 2027
A28: =A26+1 -> 22 | B28: =B27+1 -> 25 | C28: LEVASTAR 5OGRM | D28: 192 | L28: =K28+J28+I28+H28+G28+F28 -> 0 | M28: =L28/D28 -> 0 | N28: SLOW MOVING
A29: =A28+1 -> 23 | B29: =B28+1 -> 26 | C29: TRUSAN LIQUID SOAP 25LTR | D29: 1 | F29: 32 | L29: =K29+J29+I29+H29+G29+F29 -> 32 | M29: =L29/D29 -> 32 | N29: SLOW MOVING
A30: =A29+1 -> 24 | B30: =B29+1 -> 27 | C30: VETODINE 1 LTR | D30: 12 | F30: =(36*12+9)+252 -> 693 | I30: =66 -> 66 | J30: =21 -> 21 | L30: =K30+J30+I30+H30+G30+F30 -> 780 | M30: =L30/D30 -> 65 | N30: SLOW MOVING | O30: OCT, 2027
A31: =A30+1 -> 25 | B31: =B30+1 -> 28 | C31: VETODINE 25 LTR | D31: 1 | F31: 24 | I31: 10 | J31: =0 -> 0 | L31: =K31+J31+I31+H31+G31+F31 -> 34 | M31: =L31/D31 -> 34 | N31: SLOW MOVING | O31: OCT, 2027

Sheet DSL WEEK 2
A1: DSL INVENTORY REPORT FOR WEEK 2 (4TH-10TH JAN, 2026). | N1: -
A2: SKU | B2: DESCRIPTION | E2: QTY AT REGIONAL STORES. | F2: =G2-1 -> 46043.748 | G2: =NOW() -> 46044.748 | I2: ="Week"&" "&WEEKNUM(F2) -> Week 4 | M2: INVENTORY ANALYSIS | N2: EXPIRY DATE
B3: DETAILS | C3: UNIT | F3: KADUNA | G3: AWE | H3: OWERRI | I3: JOS | J3: ABUJA | K3: TOTAL STOCK | L3: REORDER LEVEL.
B4: Biosecurity | D4: REWORK | E4: GOOD
A5: 1 | B5: Bicofim -500grm | C5: PCS | E5: 0 | G5: 0 | H5: 0 | I5: 0 | K5: =D5+E5+F5+G5+H5+I5+J5 -> 0 | M5: SLOW MOVING PRODUCT
A6: =A5+1 -> 2 | B6: Biokleen 1LITRE | C6: PCS | D6: 5 | G6: =1 -> 1 | H6: 0 | I6: =0 -> 0 | K6: =D6+E6+F6+G6+H6+I6+J6 -> 6 | L6: 100 | M6: SLOW MOVING PRODUCT | N6: APR/ MAY 2026
A7: =A6+1 -> 3 | B7: Biokleen 20 Litres. | C7: KEGS | E7: 0 | G7: 0 | H7: 0 | I7: 0 | K7: =D7+E7+F7+G7+H7+I7+J7 -> 0 | L7: 50 | M7: SLOW MOVING PRODUCT
A8: =A7+1 -> 4 | B8: Biokleen 500ml | C8: PCS | E8: 0 | G8: 0 | H8: 0 | I8: 0 | K8: =D8+E8+F8+G8+H8+I8+J8 -> 0 | M8: SLOW MOVING PRODUCT
A9: =A8+1 -> 5 | B9: Citramax 1ltr | C9: PCS | D9: 8 | E9: =190 -> 190 | G9: =66 -> 66 | H9: 0 | I9: 0 | K9: =D9+E9+F9+G9+H9+I9+J9 -> 264 | L9: 100 | M9: SLOW MOVING PRODUCT
A10: =A9+1 -> 6 | B10: Citramax 20ltrs | C10: KEGS | E10: =64 -> 64 | G10: =16 -> 16 | H10: 0 | I10: =4 -> 4 | K10: =D10+E10+F10+G10+H10+I10+J10 -> 84 | L10: 50 | M10: FAST MOVING PRODUCTS | N10: OCT,2027
A11: =A10+1 -> 7 | B11: Neodine 1 Ltr | C11: PCS | D11: 5 | E11: =65 -> 65 | G11: =54 -> 54 | H11: 0 | I11: =108 -> 108 | K11: =D11+E11+F11+G11+H11+I11+J11 -> 232 | L11: 1200 | M11: FAST MOVING PRODUCTS | N11: DEC,2026
A12: =A11+1 -> 8 | B12: Neodine 20 Litres | C12: KEGS | E12: =112 -> 112 | G12: =5 -> 5 | H12: 0 | I12: =0 -> 0 | K12: =D12+E12+F12+G12+H12+I12+J12 -> 117 | L12: 100 | M12: FAST MOVING PRODUCTS | N12: OCT,2027
A13: =A12+1 -> 9 | B13: Neodine 500ml | C13: PCS | G13: 0 | H13: 0 | I13: 0 | K13: =D13+E13+F13+G13+H13+I13+J13 -> 0 | M13: SLOW MOVING PRODUCT
A14: =A13+1 -> 10 | B14: Terminator 1ltr | C14: PCS | E14: =2 -> 2 | G14: =6 -> 6 | H14: 0 | I14: =4 -> 4 | K14: =D14+E14+F14+G14+H14+I14+J14 -> 12 | L14: 100 | M14: SLOW MOVING PRODUCT | N14: APR, 2026
A15: =A14+1 -> 11 | B15: Terminator 20 ltr | C15: KEGS | H15: 0 | I15: 0 | K15: =D15+E15+F15+G15+H15+I15+J15 -> 0 | L15: 20 | M15: SLOW MOVING PRODUCT
A16: =A15+1 -> 12 | B16: Tetrasan 1ltr | C16: PCS | G16: 0 | H16: 0 | I16: 0 | K16: =D16+E16+F16+G16+H16+I16+J16 -> 0 | M16: SLOW MOVING PRODUCT
A17: =A16+1 -> 13 | B17: Tetrasan 20 Litres | C17: KEGS | G17: 0 | H17: 0 | I17: 0 | K17: =D17+E17+F17+G17+H17+I17+J17 -> 0 | M17: SLOW MOVING PRODUCT
A18: =A17+1 -> 14 | B18: Tetrasan 500ml | C18: PCS | G18: 0 | H18: 0 | I18: 0 | K18: =D18+E18+F18+G18+H18+I18+J18 -> 0 | M18: NON-MOVING PRODUCT
A19: =A18+1 -> 15 | B19: Viracid-S - 1kg | C19: PCS | H19: 0 | K19: =D19+E19+F19+G19+H19+I19+J19 -> 0 | L19: 200 | M19: FAST MOVING PRODUCTS
A20: =A19+1 -> 16 | B20: Viracid-S 5.0kg | C20: PCS | G20: 0 | H20: 0 | I20: 0 | K20: =D20+E20+F20+G20+H20+I20+J20 -> 0 | L20: 500 | M20: FAST MOVING PRODUCTS
A21: =A20+1 -> 17 | B21: Viracid-S 20 kg | C21: DRUMS | H21: 0 | I21: 0 | K21: =D21+E21+F21+G21+H21+I21+J21 -> 0 | L21: 100 | M21: FAST MOVING PRODUCTS
A22: =A21+1 -> 18 | B22: Wyldox 500GM | C22: PCS | E22: =3120 -> 3120 | G22: 400 | H22: 0 | I22: =0 -> 0 | K22: =D22+E22+F22+G22+H22+I22+J22 -> 3520 | M22: SLOW MOVING PRODUCT | N22: MAY, 2026
A23: =A22+1 -> 19 | B23: Wyldox 100GM | C23: PCS | G23: 0 | H23: 0 | I23: 0 | K23: =D23+E23+F23+G23+H23+I23+J23 -> 0 | M23: SLOW MOVING PRODUCT
A24: =A23+1 -> 20 | B24: Wyldox 20GM | C24: PCS | G24: 0 | H24: 0 | I24: 0 | K24: =D24+E24+F24+G24+H24+I24+J24 -> 0 | M24: SLOW MOVING PRODUCT
A25: =A24+1 -> 21 | B25: WYLDOX TABLET (10G *100PCS) | C25: PCS | E25: =(2000*14)+798 -> 28798 | G25: =2100 -> 2100 | H25: 450 | I25: =515+6000 -> 6515 | K25: =D25+E25+F25+G25+H25+I25+J25 -> 37863 | M25: NEW PRODUCT ON OBSERVATION | N25: 46844
B26: SUB TOTAL(Biosecurity) | K26: =D26+E26+F26+G26+H26+I26+J26 -> 0
B27: Concentrates | C27: UNIT | G27: 0 | K27: =D27+E27+F27+G27+H27+I27+J27 -> 0 | L27: REORDER LEVEL.
A28: 1 | B28: Biokleen Concentrate 25ltr | C28: LITRES | G28: 0 | K28: =D28+E28+F28+G28+H28+I28+J28 -> 0 | L28: 1000 | M28: SLOW MOVING PRODUCT
A29: 2 | B29: Citramax Concentrate - 25ltr | C29: LITRES | E29: =100 -> 100 | G29: 0 | K29: =D29+E29+F29+G29+H29+I29+J29 -> 100 | L29: 500 | M29: SLOW MOVING PRODUCT | N29: MAR, 2027
A30: 3 | B30: Neodine Concentrate | C30: LITRES | E30: =19*25 -> 475 | G30: 0 | K30: =D30+E30+F30+G30+H30+I30+J30 -> 475 | L30: 1500 | M30: FAST MOVING PRODUCTS | N30: MAR, 2027
A31: 4 | B31: Terminator 111 Concentrate 25ltr | C31: LITRES | G31: 0 | K31: =D31+E31+F31+G31+H31+I31+J31 -> 0 | L31: 300 | M31: SLOW MOVING PRODUCT
A32: 5 | B32: Tetrasan Concentrate 25ltr | C32: LITRES | G32: 0 | K32: =D32+E32+F32+G32+H32+I32+J32 -> 0
B33: SUB TOTAL(Concentrates) | G33: 0 | K33: =D33+E33+F33+G33+H33+I33+J33 -> 0
B34: Drugs | C34: UNIT | G34: 0 | K34: =D34+E34+F34+G34+H34+I34+J34 -> 0 | L34: REORDER LEVEL.
A35: 1 | B35: Avertin Oralsolution 1% 100ml | C35: PCS | E35: =6900-192 -> 6708 | G35: =98 -> 98 | H35: 5 | I35: 58 | K35: =D35+E35+F35+G35+H35+I35+J35 -> 6869 | L35: 1000 | M35: SLOW MOVING PRODUCT | N35: MAR, 2027
A36: =A35+1 -> 2 | B36: Ds-LivorTon Liquid-500ml | C36: PCS | K36: =D36+E36+F36+G36+H36+I36+J36 -> 0 | L36: 2000 | M36: SLOW MOVING PRODUCT | N36: JUN,2026
A37: =A36+1 -> 3 | B37: DS-Siproxin 10%-100gm | C37: PCS | H37: 0 | I37: 0 | K37: =D37+E37+F37+G37+H37+I37+J37 -> 0 | L37: 5000 | M37: FAST MOVING PRODUCTS
A38: =A37+1 -> 4 | B38: Megadox-N 100gm | C38: PCS | G38: 0 | H38: 0 | I38: 0 | K38: =D38+E38+F38+G38+H38+I38+J38 -> 0 | L38: 5000 | M38: FAST MOVING PRODUCTS
A39: =A38+1 -> 5 | B39: Oxy-100-FS - 10kg | C39: PCS | G39: 0 | H39: 0 | I39: 0 | K39: =D39+E39+F39+G39+H39+I39+J39 -> 0 | L39: 100 | M39: SLOW MOVING PRODUCT
A40: =A39+1 -> 6 | B40: QUINROCIN ORAL 1 LTRE | C40: PCS | E40: =1296 -> 1296 | G40: 12 | H40: 0 | I40: =20 -> 20 | K40: =D40+E40+F40+G40+H40+I40+J40 -> 1328 | L40: 1000 | M40: SLOW MOVING PRODUCT | N40: MAR, 2027
...

Sheet SLOW MOVING
A1: SLOW DSL INVENTORY REPORT FOR REPORT FOR WEEK 2 (4TH-10TH JAN, 2026).
A2: SKU | B2: DESCRIPTION | D2: QTY AT REGIONAL STORES. | E2: =F2-1 -> 46043.748 | F2: =NOW() -> 46044.748 | H2: ="Week"&" "&WEEKNUM(E2) -> Week 4 | K2: REORDER LEVEL. | L2: INVENTORY ANALYSIS | M2: EXPIRY DATE
B3: Biosecurity | C3: UNIT | D3: LAGOS | E3: KADUNA | F3: AWE | G3: OWERRI | H3: JOS | I3: ABUJA | J3: TOTAL STOCK | K3: REORDER LEVEL.
A4: 1 | B4: Biokleen 1LITRE | C4: PCS | D4: ='DSL WEEK 2'!E6 -> 0 | E4: ='DSL WEEK 2'!F6 -> 0 | F4: ='DSL WEEK 2'!G6 -> 1 | G4: ='DSL WEEK 2'!H6 -> 0 | H4: ='DSL WEEK 2'!I6 -> 0 | I4: ='DSL WEEK 2'!J6 -> 0 | J4: ='DSL WEEK 2'!K6 -> 6 | K4: ='DSL WEEK 2'!L6 -> 100 | ... M4: ='DSL WEEK 2'!N6 -> APR/ MAY 2026
A5: =A4+1 -> 2 | B5: Biokleen 20 Litres. | C5: KEGS | D5: ='DSL WEEK 2'!E7 -> 0 | E5: ='DSL WEEK 2'!F7 -> 0 | F5: ='DSL WEEK 2'!G7 -> 0 | G5: ='DSL WEEK 2'!H7 -> 0 | H5: ='DSL WEEK 2'!I7 -> 0 | I5: ='DSL WEEK 2'!J7 -> 0 | J5: ='DSL WEEK 2'!K7 -> 0 | K5: ='DSL WEEK 2'!L7 -> 50 | ... M5: ='DSL WEEK 2'!N7 -> 0
A6: =A5+1 -> 3 | B6: Terminator 1ltr | C6: PCS | D6: ='DSL WEEK 2'!E14 -> 2 | E6: ='DSL WEEK 2'!F14 -> 0 | F6: ='DSL WEEK 2'!G14 -> 6 | G6: ='DSL WEEK 2'!H14 -> 0 | H6: ='DSL WEEK 2'!I14 -> 4 | I6: ='DSL WEEK 2'!J14 -> 0 | J6: ='DSL WEEK 2'!K14 -> 12 | K6: ='DSL WEEK 2'!L14 -> 100 | ... M6: ='DSL WEEK 2'!N14 -> APR, 2026
A7: =A6+1 -> 4 | B7: Terminator 20 ltr | C7: KEGS | D7: ='DSL WEEK 2'!E15 -> 0 | H7: 0 | J7: =D7+E7+F7+G7+H7+I7 -> 0 | K7: 20 | L7: SLOW MOVING PRODUCT | M7: DEC, 2025
A8: =A7+1 -> 5 | B8: Viracid-S - 1kg | C8: PCS | J8: =D8+E8+F8+G8+H8+I8 -> 0 | K8: 200 | L8: SLOW MOVING PRODUCT | M8: DEC,2025
A9: =A8+1 -> 6 | B9: Viracid-S 20 kg | C9: DRUMS | D9: ='DSL WEEK 2'!E21 -> 0 | E9: ='DSL WEEK 2'!F21 -> 0 | F9: ='DSL WEEK 2'!G21 -> 0 | G9: ='DSL WEEK 2'!H21 -> 0 | H9: ='DSL WEEK 2'!I21 -> 0 | I9: ='DSL WEEK 2'!J21 -> 0 | J9: =D9+E9+F9+G9+H9+I9 -> 0 | K9: 100 | L9: SLOW MOVING PRODUCT | M9: DEC,2025
A10: =A9+1 -> 7 | B10: Wyldox 500GM | C10: PCS | D10: ='DSL WEEK 2'!E22 -> 3120 | E10: ='DSL WEEK 2'!F22 -> 0 | F10: ='DSL WEEK 2'!G22 -> 400 | G10: ='DSL WEEK 2'!H22 -> 0 | H10: ='DSL WEEK 2'!I22 -> 0 | I10: ='DSL WEEK 2'!J22 -> 0 | J10: =D10+E10+F10+G10+H10+I10 -> 3520 | L10: SLOW MOVING PRODUCT | M10: MAY, 2026
B11: SUB TOTAL(Biosecurity) | J11: =D11+E11+F11+G11+H11+I11 -> 0
B12: Concentrates | C12: UNIT | J12: =D12+E12+F12+G12+H12+I12 -> 0 | K12: REORDER LEVEL.
A13: 1 | B13: Biokleen Concentrate 25ltr | C13: LITRES | D13: ='DSL WEEK 2'!E28 -> 0 | E13: ='DSL WEEK 2'!F28 -> 0 | F13: ='DSL WEEK 2'!G28 -> 0 | G13: ='DSL WEEK 2'!H28 -> 0 | H13: ='DSL WEEK 2'!I28 -> 0 | I13: ='DSL WEEK 2'!J28 -> 0 | J13: ='DSL WEEK 2'!K28 -> 0 | L13: ='DSL WEEK 2'!M28 -> SLOW MOVING PRODUCT | M13: ='DSL WEEK 2'!N28 -> 0
B14: SUB TOTAL(Concentrates) | J14: =D14+E14+F14+G14+H14+I14 -> 0
B15: Drugs | C15: UNIT | J15: =D15+E15+F15+G15+H15+I15 -> 0 | K15: REORDER LEVEL.
A16: 1 | B16: Avertin Oralsolution 1% 100ml | C16: PCS | D16: ='DSL WEEK 2'!E35 -> 6708 | E16: ='DSL WEEK 2'!F35 -> 0 | F16: ='DSL WEEK 2'!G35 -> 98 | G16: ='DSL WEEK 2'!H35 -> 5 | H16: ='DSL WEEK 2'!I35 -> 58 | I16: ='DSL WEEK 2'!J35 -> 0 | J16: ='DSL WEEK 2'!K35 -> 6869 | K16: ='DSL WEEK 2'!L35 -> 1000 | ... M16: ='DSL WEEK 2'!N35 -> MAR, 2027
A17: =A16+1 -> 2 | B17: Ds-LivorTon Liquid-500ml | C17: PCS | D17: ='DSL WEEK 2'!E36 -> 0 | E17: ='DSL WEEK 2'!F36 -> 0 | F17: ='DSL WEEK 2'!G36 -> 0 | G17: ='DSL WEEK 2'!H36 -> 0 | H17: ='DSL WEEK 2'!I36 -> 0 | I17: ='DSL WEEK 2'!J36 -> 0 | J17: ='DSL WEEK 2'!K36 -> 0 | K17: ='DSL WEEK 2'!L36 -> 2000 | ... M17: ='DSL WEEK 2'!N36 -> JUN,2026
A18: =A17+1 -> 3 | B18: QUINROCIN ORAL 1 LTRE | C18: PCS | D18: ='DSL WEEK 2'!E40 -> 1296 | E18: ='DSL WEEK 2'!F40 -> 0 | F18: ='DSL WEEK 2'!G40 -> 12 | G18: ='DSL WEEK 2'!H40 -> 0 | H18: ='DSL WEEK 2'!I40 -> 20 | I18: ='DSL WEEK 2'!J40 -> 0 | J18: ='DSL WEEK 2'!K40 -> 1328 | K18: ='DSL WEEK 2'!L40 -> 1000 | ... M18: ='DSL WEEK 2'!N40 -> MAR, 2027
A19: =A18+1 -> 4 | B19: Ultra -TM Plus 500ml | C19: PCS | D19: ='DSL WEEK 2'!E43 -> 0 | E19: ='DSL WEEK 2'!F43 -> 0 | F19: ='DSL WEEK 2'!G43 -> 0 | G19: ='DSL WEEK 2'!H43 -> 0 | H19: ='DSL WEEK 2'!I43 -> 0 | I19: ='DSL WEEK 2'!J43 -> 0 | J19: ='DSL WEEK 2'!K43 -> 0 | K19: ='DSL WEEK 2'!L43 -> 1500 | ... M19: ='DSL WEEK 2'!N43 -> 0
B20: Premixes | J20: =D20+E20+F20+G20+H20+I20 -> 0
A21: 1 | B21: A-GEEMIX FORTE | C21: PCS | D21: ='DSL WEEK 2'!E102 -> 0 | E21: ='DSL WEEK 2'!F102 -> 0 | F21: ='DSL WEEK 2'!G102 -> 0 | G21: ='DSL WEEK 2'!H102 -> 20 | H21: ='DSL WEEK 2'!I102 -> 0 | I21: ='DSL WEEK 2'!J102 -> 0 | J21: ='DSL WEEK 2'!K102 -> 20 | K21: ='DSL WEEK 2'!L102 -> 0 | ... M21: ='DSL WEEK 2'!N102 -> JUN,2026
A22: =A21+1 -> 2 | B22: KIKSTART-CXL 1KG | C22: PCS | D22: ='DSL WEEK 2'!E105 -> 0 | E22: ='DSL WEEK 2'!F105 -> 0 | F22: ='DSL WEEK 2'!G105 -> 0 | G22: ='DSL WEEK 2'!H105 -> 0 | H22: ='DSL WEEK 2'!I105 -> 0 | I22: ='DSL WEEK 2'!J105 -> 0 | J22: =D22+E22+F22+G22+H22+I22 -> 0 | L22: SLOW MOVING PRODUCT
A23: =A22+1 -> 3 | B23: Phytocee - 25kg | C23: BAGS | D23: ='DSL WEEK 2'!E109 -> 162 | E23: ='DSL WEEK 2'!F109 -> 0 | F23: ='DSL WEEK 2'!G109 -> 0 | G23: ='DSL WEEK 2'!H109 -> 0 | H23: ='DSL WEEK 2'!I109 -> 7 | I23: ='DSL WEEK 2'!J109 -> 0 | J23: ='DSL WEEK 2'!K109 -> 169 | K23: ='DSL WEEK 2'!L109 -> 0 | ... M23: ='DSL WEEK 2'!N109 -> 0
A24: =A23+1 -> 4 | B24: Stodi - 25kg | C24: BAGS | D24: ='DSL WEEK 2'!E112 -> 0 | E24: ='DSL WEEK 2'!F112 -> 0 | F24: ='DSL WEEK 2'!G112 -> 17 | G24: ='DSL WEEK 2'!H112 -> 0 | H24: ='DSL WEEK 2'!I112 -> 2 | I24: ='DSL WEEK 2'!J112 -> 0 | J24: ='DSL WEEK 2'!K112 -> 19 | K24: ='DSL WEEK 2'!L112 -> 0 | ... M24: ='DSL WEEK 2'!N112 -> DEC,2025
A25: =A24+1 -> 5 | B25: Topicure Spray 250ml (25/ctn) | C25: PCS | D25: ='DSL WEEK 2'!E113 -> 0 | E25: ='DSL WEEK 2'!F113 -> 0 | F25: ='DSL WEEK 2'!G113 -> 888 | G25: ='DSL WEEK 2'!H113 -> 0 | H25: ='DSL WEEK 2'!I113 -> 37 | I25: ='DSL WEEK 2'!J113 -> 0 | J25: ='DSL WEEK 2'!K113 -> 925 | K25: ='DSL WEEK 2'!L113 -> 1000 | ... M25: ='DSL WEEK 2'!N113 -> OCT,2025
A26: =A25+1 -> 6
A27: =A26+1 -> 7 | B27: Zigbir Powder -25kg | C27: BAGS | D27: ='DSL WEEK 2'!E115 -> 5 | E27: ='DSL WEEK 2'!F115 -> 0 | F27: ='DSL WEEK 2'!G115 -> 16 | G27: ='DSL WEEK 2'!H115 -> 0 | H27: ='DSL WEEK 2'!I115 -> 12 | I27: ='DSL WEEK 2'!J115 -> 0 | J27: ='DSL WEEK 2'!K115 -> 33 | K27: ='DSL WEEK 2'!L115 -> 200 | ... M27: ='DSL WEEK 2'!N115 -> MAY, 2026
B28: SUB TOTAL(PACKAGING)
B31: FINISHED PRODUCTS | C31: CONDITIONING | D31: LAGOS | E31: OWERRI | F31: ABJ | G31: AWE | H31: JOS | I31: KADUNA | J31: TOTAL | K31: EXPIRY DATE
B32: ='DSLP FG WK 2'!C5 -> COXSTOP 100GRM | C32: 96 | D32: ='DSLP FG WK 2'!F5 -> 2256 | E32: ='DSLP FG WK 2'!G5 -> 0 | F32: ='DSLP FG WK 2'!H5 -> 0 | G32: ='DSLP FG WK 2'!I5 -> 48 | H32: ='DSLP FG WK 2'!J5 -> 576 | I32: ='DSLP FG WK 2'!K5 -> 0 | J32: ='DSLP FG WK 2'!L5 -> 2880 | K32: ='DSLP FG WK 2'!O5 -> MAR, 2027
B33: DISULTRIM 100GRM | C33: 96 | D33: ='DSLP FG WK 2'!F7 -> 5 | E33: ='DSLP FG WK 2'!G7 -> 0 | F33: ='DSLP FG WK 2'!H7 -> 0 | G33: ='DSLP FG WK 2'!I7 -> 47 | H33: ='DSLP FG WK 2'!J7 -> 75 | I33: ='DSLP FG WK 2'!K7 -> 0 | J33: =D33+E33+F33+G33+H33+I33 -> 127 | K33: NOV,2025
B34: DIVERCAL-D | C34: 12 | D34: ='DSLP FG WK 2'!F9 -> 9 | E34: ='DSLP FG WK 2'!G9 -> 26 | F34: ='DSLP FG WK 2'!H9 -> 0 | G34: ='DSLP FG WK 2'!I9 -> 3 | H34: ='DSLP FG WK 2'!J9 -> 89 | I34: ='DSLP FG WK 2'!K9 -> 0 | J34: ='DSLP FG WK 2'!L9 -> 127 | K34: ='DSLP FG WK 2'!O9 -> AUG, 2027
B35: ='DSLP FG WK 2'!C15 -> DIVERFLOX 100GRM | C35: 96 | D35: ='DSLP FG WK 2'!F15 -> 0 | E35: ='DSLP FG WK 2'!G15 -> 0 | F35: ='DSLP FG WK 2'!H15 -> 0 | G35: ='DSLP FG WK 2'!I15 -> 28 | H35: ='DSLP FG WK 2'!J15 -> 736 | I35: ='DSLP FG WK 2'!K15 -> 0 | J35: ='DSLP FG WK 2'!L15 -> 764 | K35: ='DSLP FG WK 2'!O15 -> NOV, 2027
B36: DIVERTAMIN | C36: 96 | D36: ='DSLP FG WK 2'!F18 -> 357 | E36: ='DSLP FG WK 2'!G18 -> 192 | F36: ='DSLP FG WK 2'!H18 -> 0 | G36: ='DSLP FG WK 2'!I18 -> 158 | H36: ='DSLP FG WK 2'!J18 -> 1058 | I36: ='DSLP FG WK 2'!K18 -> 0 | J36: =D36+E36+F36+G36+H36+I36 -> 1765 | K36: DEC,2025
B37: DOXINEO 100GRM | C37: 96 | D37: ='DSLP FG WK 2'!F20 -> 0 | E37: ='DSLP FG WK 2'!G20 -> 0 | F37: ='DSLP FG WK 2'!H20 -> 0 | G37: ='DSLP FG WK 2'!I20 -> 0 | H37: ='DSLP FG WK 2'!J20 -> 0 | I37: ='DSLP FG WK 2'!K20 -> 0 | J37: =D37+E37+F37+G37+H37+I37 -> 0
B38: ENRO 1 LTR | C38: 12 | D38: ='DSLP FG WK 2'!F22 -> 1 | E38: ='DSLP FG WK 2'!G22 -> 19 | F38: ='DSLP FG WK 2'!H22 -> 0 | G38: ='DSLP FG WK 2'!I22 -> 22 | H38: ='DSLP FG WK 2'!J22 -> 0 | I38: ='DSLP FG WK 2'!K22 -> 0 | J38: ='DSLP FG WK 2'!L22 -> 42 | K38: ='DSLP FG WK 2'!O22 -> MAY, 2027
B39: TRUSAN LIQUID SOAP 25LTR | C39: 1 | D39: ='DSLP FG WK 2'!F29 -> 32 | E39: ='DSLP FG WK 2'!G29 -> 0 | F39: ='DSLP FG WK 2'!H29 -> 0 | G39: ='DSLP FG WK 2'!I29 -> 0 | H39: ='DSLP FG WK 2'!J29 -> 0 | I39: ='DSLP FG WK 2'!K29 -> 0 | J39: =D39+E39+F39+G39+H39+I39 -> 32
B40: ='DSLP FG WK 2'!C12 -> DIVERCOOL C 25Litres | C40: ='DSLP FG WK 2'!D12 -> 1 | D40: ='DSLP FG WK 2'!F12 -> 15 | E40: ='DSLP FG WK 2'!G12 -> 0 | F40: ='DSLP FG WK 2'!H12 -> 0 | G40: ='DSLP FG WK 2'!I12 -> 10 | H40: ='DSLP FG WK 2'!J12 -> 2 | I40: ='DSLP FG WK 2'!K12 -> 0 | J40: ='DSLP FG WK 2'!L12 -> 27 | K40: ='DSLP FG WK 2'!O11 -> 0

Sheet SHELF LIFE ANALYSIS
B1: SHELF LIFE ANALYSIS FOR THE TOP NEAR EXPIRED FOR WEEK 9(23rD FEB-1st MAR, 2025) | T1: =U1 -> 46044.748 | U1: =NOW() -> 46044.748 | W1: ="Week"&" "&WEEKNUM(T1) -> Week 4
D2: CRITICAL ANALYSIS FOR NEAR EXPIRED REPORT FOR WEEK 2 (4TH-10TH JAN, 2026).
B3: Trade Mark Name | C3: Product Name | D3: Qty Available. | E3: Store | F3: Batch Numb. | G3: Manufacturing Date | H3: Expiring Date | I3: Today's Date | K3: Days Spent | L3: Shelf-Life | M3: Qtr M1 | N3: Qtr M2 | O3: Qtr M3 | P3: Qtr M4 | Q3: Indicator | R3: Index | S3: Store Remark
A4: 1 | B4: BHARTI | C4: Wyldox 500GM | D4: ='SLOW MOVING'!J10 -> 3520 | E4: ALL REGION | F4: SR/WLT/A111 | G4: 44347 | H4: 46173 | I4: =NOW() -> 46044.748 | K4: 1629 | L4: 1826 | M4: 456.5 | N4: 456.5 | O4: 456.5 | P4: 456.5 | Q4: Warning | R4: 0.89211391 | S4: In - Store
A5: =A4+1 -> 2 | B5: NATURAL REMEDIES | C5: Topicure Spray 250ml (25/ctn) | D5: ='SLOW MOVING'!J25 -> 925 | E5: ALL REGION | F5: 22J002 | G5: 44895 | H5: 45961 | K5: 1045 | L5: 1066 | M5: 266.5 | N5: 266.5 | O5: 266.5 | P5: 266.5 | Q5: Warning | R5: 0.98030019 | S5: In - Store
A6: =A5+1 -> 3 | B6: NATURAL REMEDIES | C6: STODI | D6: ='SLOW MOVING'!J24 -> 19 | E6: LAGOS/AWE | G6: 45322 | H6: 46022 | K6: 502 | L6: 700 | M6: 175 | N6: 175 | O6: 175 | P6: 175 | Q6: Barely Fair | R6: 0.55857143 | S6: In - Store
A7: =A6+1 -> 4 | B7: NATURAL REMEDIES | C7: Phytocee - 25kg | D7: ='SLOW MOVING'!J23 -> 169 | E7: LAGOS/JOS | G7: 45322 | H7: 46022 | K7: 502 | L7: 700 | M7: 175 | N7: 175 | O7: 175 | P7: 175 | Q7: Barely Fair | R7: 0.55857143 | S7: In - Store
B8: NEOSPARK | C8: A-GEEMIX FORTE | D8: ='SLOW MOVING'!J21 -> 20 | E8: ALL REGION | F8: 2180480 | G8: 45504 | H8: 46203 | K8: 320 | L8: 699 | M8: 174.75 | N8: 174.75 | O8: 174.75 | P8: 174.75 | Q8: Good 2 | R8: 0.29899857 | S8: In - Store
A9: =A7+1 -> 5 | B9: NEOSPARK | C9: QUINROCIN ORAL 1 LTRE | D9: ='SLOW MOVING'!J18 -> 1328 | E9: ALL REGION | F9: 7322008 | G9: 45777 | H9: 46477 | K9: 199 | L9: 700 | M9: 175.75 | N9: 175.75 | O9: 175.75 | P9: 175.75 | Q9: Good 2 | R9: 0.51635846 | S9: In - Store
A10: =A9+1 -> 6 | B10: NEOSPARK | C10: Ds-LivorTon Liquid-500ml | D10: ='SLOW MOVING'!J17 -> 0 | E10: OWERI | F10: 2290008 | G10: 45504 | H10: 46203 | K10: 533 | L10: 760 | M10: 190 | N10: 190 | O10: 190 | P10: 190 | Q10: Barely Fair | R10: 0.70131579 | S10: In - Store
B11: NEOSPARK | C11: Avertin Oralsolution 1% 100ml | D11: ='DSL WEEK 2'!K35 -> 6869 | E11: ALL REGION | G11: 45350 | H11: 46053 | K11: 551 | L11: 703 | M11: 175.75 | N11: 175.75 | O11: 175.75 | P11: 175.75 | Q11: Warning | R11: =IFERROR((K11/L11),"") -> 0.78378378 | S11: In - Store
C12: ='DSL WEEK 2'!B6 -> Biokleen 1LITRE | D12: ='DSL WEEK 2'!K6 -> 6 | E12: ALL REGION | Q12: Barely Fair
C13: ='DSL WEEK 2'!B7 -> Biokleen 20 Litres. | D13: ='DSL WEEK 2'!K7 -> 0 | E13: ALL REGION | Q13: Barely Fair
C14: ='DSL WEEK 2'!B14 -> Terminator 1ltr | D14: ='DSL WEEK 2'!K14 -> 12 | E14: ALL REGION | G14: 45443 | H14: 46142 | K14: 533 | L14: 699 | M14: 175 | N14: 175 | O14: 175 | P14: 175 | Q14: Warning | R14: 0.76251788 | S14: In - Store
C15: ='DSL WEEK 2'!B6 -> Biokleen 1LITRE | D15: ='DSL WEEK 2'!K6 -> 6 | E15: LAG/JOS | G15: 45443 | H15: 46142 | K15: 533 | L15: 699 | M15: 175 | N15: 175 | O15: 175 | P15: 175 | Q15: Warning | R15: 0.76251788 | S15: In - Store

Sheet STOCK OUT
A2: SKU | B2: DESCRIPTION | D2: QTY AT REGIONAL STORES. | E2: =F2 -> 46044.748 | F2: =NOW() -> 46044.748 | H2: ="Week"&" "&WEEKNUM(E2) -> Week 4 | L2: INVENTORY ANALYSIS | M2: %
B3: Biosecurity | C3: UNIT | D3: LAGOS | E3: KADUNA | F3: AWE | G3: OWERRI | H3: JOS | I3: ABUJA | J3: TOTAL STOCK | K3: REORDER LEVEL.
A4: 1 | B4: Viracid-S 20 kg | J4: =D4+E4+F4+G4+H4+I4 -> 0
B5: Concentrates | C5: UNIT | J5: =D5+E5+F5+G5+H5+I5 -> 0
A6: 1 | B6: Terminator 111 Concentrate 25ltr | C6: LITRES | D6: 0 | J6: =D6+E6+F6+G6+H6+I6 -> 0 | K6: 300 | L6: SLOW MOVING PRODUCT
B7: SUB TOTAL(Concentrates) | J7: =D7+E7+F7+G7+H7+I7 -> 0
B8: Drugs | C8: UNIT | J8: =D8+E8+F8+G8+H8+I8 -> 0 | K8: REORDER LEVEL.
A9: 1 | B9: Megadox-N 100gm | C9: PCS | D9: ='DSL WEEK 2'!E38 -> 0 | E9: ='DSL WEEK 2'!F38 -> 0 | F9: ='DSL WEEK 2'!G38 -> 0 | G9: ='DSL WEEK 2'!H38 -> 0 | H9: ='DSL WEEK 2'!I38 -> 0 | I9: ='DSL WEEK 2'!J38 -> 0 | J9: ='DSL WEEK 2'!K38 -> 0 | K9: ='DSL WEEK 2'!L38 -> 5000 | L9: ='DSL WEEK 2'!M38 -> FAST MOVING PRODUCTS
A10: =A9+1 -> 2 | B10: DS-Siproxin 10%-100gm | C10: PCS | D10: ='DSL WEEK 2'!E37 -> 0 | E10: ='DSL WEEK 2'!F37 -> 0 | F10: ='DSL WEEK 2'!G37 -> 0 | G10: ='DSL WEEK 2'!H37 -> 0 | H10: ='DSL WEEK 2'!I37 -> 0 | I10: ='DSL WEEK 2'!J37 -> 0 | J10: ='DSL WEEK 2'!K37 -> 0 | K10: 5000 | L10: ='DSL WEEK 2'!M42 -> FAST MOVING PRODUCTS
B11: Premixes | J11: =D11+E11+F11+G11+H11+I11 -> 0 | K11: 2000
A12: 1 | B12: Curatox-Fs | C12: BAGS | D12: 0 | H12: 3 | J12: =D12+E12+F12+G12+H12+I12 -> 3 | L12: FAST MOVING PRODUCTS
A13: =A12+1 -> 2 | B13: Zigbir Liquid 1 ltre. | C13: PCS | J13: =D13+E13+F13+G13+H13+I13 -> 0 | L13: FAST MOVING PRODUCTS
B14: SUB TOTAL(PACKAGING)
